INFO - predict.py - 2025-01-23 11:48:05,335 - Loading config from /gws/nopw/j04/bris_climdyn/j_miller/temp/config.yml
INFO - _timer.py - 2025-01-23 11:48:05,391 - sample: 0.0 minutes
OSError: [Errno 122] Disk quota exceeded

During handling of the above exception, another exception occurred:

Traceback (most recent call last):
  File "/home/users/j_miller/mlde_Josh/bin/predict.py", line 325, in <module>
    app()
  File "/home/users/j_miller/miniforge3/envs/mlde_Josh/lib/python3.9/site-packages/typer/main.py", line 328, in __call__
    raise e
  File "/home/users/j_miller/miniforge3/envs/mlde_Josh/lib/python3.9/site-packages/typer/main.py", line 311, in __call__
    return get_command(self)(*args, **kwargs)
  File "/home/users/j_miller/miniforge3/envs/mlde_Josh/lib/python3.9/site-packages/click/core.py", line 1130, in __call__
    return self.main(*args, **kwargs)
  File "/home/users/j_miller/miniforge3/envs/mlde_Josh/lib/python3.9/site-packages/typer/core.py", line 716, in main
    return _main(
  File "/home/users/j_miller/miniforge3/envs/mlde_Josh/lib/python3.9/site-packages/typer/core.py", line 216, in _main
    rv = self.invoke(ctx)
  File "/home/users/j_miller/miniforge3/envs/mlde_Josh/lib/python3.9/site-packages/click/core.py", line 1404, in invoke
    return ctx.invoke(self.callback, **ctx.params)
  File "/home/users/j_miller/miniforge3/envs/mlde_Josh/lib/python3.9/site-packages/click/core.py", line 760, in invoke
    return __callback(*args, **kwargs)
  File "/home/users/j_miller/miniforge3/envs/mlde_Josh/lib/python3.9/site-packages/typer/main.py", line 683, in wrapper
    return callback(**use_params)  # type: ignore
  File "/home/users/j_miller/miniforge3/envs/mlde_Josh/lib/python3.9/contextlib.py", line 79, in inner
    return func(*args, **kwds)
  File "/home/users/j_miller/mlde_Josh/bin/predict.py", line 279, in main
    f.write(config.to_yaml())
OSError: [Errno 122] Disk quota exceeded

real	0m5.547s
user	0m1.800s
sys	0m0.897s
